Workbook

Sheet README
A1: JHS BEHAVIORAL HEALTH STAFFING MODEL — V2 (Facility-Split)
A2: KCCF and MRJC calculated independently from 2025 workload volumes
A4: What's new in V2
A5: Every activity is now calculated separately for KCCF and MRJC using that facility's actual 2025 workload volumes from the synthetic dataset. For per-position activities, positions are specified per facility (e.g., infirmary RN coverage is 3 positions at KCCF and 3 at MRJC rather than 6 combined). The Summary sheet rolls up by role × facility so you can see each facility's gap against its share of current Division FTE.
A7: Why this matters
A8: KCCF carries more bookings (11,051 vs 6,905), more psych-housing census (67 vs 52), and is the primary psychiatric housing location — but MRJC has a materially larger MOUD census (123 vs 82 per the Jan 2026 snapshot). A facility-split model shows leadership not just 'we need more FTE' but 'we need more nursing at KCCF and more MOUD-adjacent staffing at MRJC.'
A10: Method (unchanged from V1)
A11: • Per-encounter: FTE = (Annual Volume × Minutes per Unit) ÷ Productive Minutes per FTE per Year
A12: • Per-position: FTE = Positions × Coverage Factor
A13: • Productive minutes per FTE = 2,080 hrs × (1 − 20% non-productive) × 60 = 99,840 min
A15: Sheets
A16: 1. README — this sheet
... A26: Time standards and positions are editable on each facility tab (blue text on yellow). All calculations live-update. For a real budget submission, validate every time-per-unit with the role-group lead responsible for the service at that facility — KCCF and MRJC have different physical layouts and service intensities, so the same activity may legitimately take different amounts of time at each site.

Sheet Volumes_2025
A1: 2025 Activity Volumes — by Facility
A3: Activity | B3: KCCF | C3: MRJC | D3: Total | E3: Source / notes
A4: adp_avg_combined | B4: 790 | C4: 621 | D4: =B4+C4 -> 1411 | E4: Average daily population
A5: bookings_annual | B5: 11051 | C5: 6905 | D5: =B5+C5 -> 17956 | E5: KCCF is primary booking facility
A6: releases_annual | B6: 10749 | C6: 6694 | D6: =B6+C6 -> 17443 | E6: Approximately equal to bookings
A7: releases_after_hours_annual | B7: 2771 | C7: 1678 | D7: =B7+C7 -> 4449 | E7: Outside 12-hr pharmacy/coord-discharge window
A8: bh_med_orders_annual | B8: 1798 | C8: 1063 | D8: =B8+C8 -> 2861 | E8: ~18% of bookings per 2023 audit
A9: med_changes_annual | B9: 30 | C9: 0 | D9: =B9+C9 -> 30 | E9: Changes + discontinuations at booking (Audit Rec #6)
A10: psych_clinic_appts_completed | B10: 1947 | C10: 2020 | D10: =B10+C10 -> 3967 | E10: General-population completed clinic appts
A11: psych_housing_appts_completed | B11: 3493 | C11: 3451 | D11: =B11+C11 -> 6944 | E11: Psych-housing completed appts
A12: psych_housing_census_avg | B12: 67 | C12: 52 | D12: =B12+C12 -> 119 | E12: KCCF is primary psychiatric housing site
A13: infirmary_census_avg | B13: 39 | C13: 30 | D13: =B13+C13 -> 69 | E13: Average patients in 24-hr skilled nursing
A14: suicide_watch_avg | B14: 11 | C14: 8 | D14: =B14+C14 -> 19 | E14: DAJD-supervised; RN oversight required
A15: sick_call_annual | B15: 15640 | C15: 12224 | D15: =B15+C15 -> 27864 | E15: Unscheduled clinical demand
... A39: medicaid_reimbursable_encounters_annual | B39: 0 | C39: 0 | D39: =B39+C39 -> 0 | E39: 1115 Waiver — zero in 2025

Sheet Productivity
A1: Global Productivity Assumptions
A3: Assumption | B3: Value | C3: Source / notes
A4: annual_hours_per_fte | B4: 2080 | C4: Standard 40 hrs × 52 weeks
A5: nonproductive_rate | B5: 0.2 | C5: PTO, sick, training, meetings, admin overhead
A6: productive_hours_per_fte | B6: =B4*(1-B5) -> 1664 | C6: Formula: annual × (1 − non-productive)
A7: productive_minutes_per_fte | B7: =B6*60 -> 99840 | C7: Used as denominator for per-encounter FTE calculations

Sheet Coverage_Factors
A1: Coverage Factors for Per-Position Staffing
A3: Coverage pattern | B3: FTE per position | C3: Notes
A4: 24_7_single_point | B4: 4.2 | C4: 8,760 hrs/yr ÷ 2,080 productive = 4.21. Use for infirmary, charge nurse, on-call.
A5: 7_day_12_hour | B5: 2.1 | C5: 4,380 hrs/yr ÷ 2,080. For 12-hr coverage 7 days/wk (e.g., pharmacy).
A6: 5_day_8_hour | B6: 1 | C6: 2,080 hrs/yr ÷ 2,080. Standard weekday day-shift role.
A7: 5_day_8_hour_with_pto_buffer | B7: 1.2 | C7: 1.0 × 1.2 buffer for leave. Common for supervisors.
A8: 12_hour_overnight_coverage | B8: 1.6 | C8: For partial-shift coverage e.g., evening/night PES
A9: on_call_overlay | B9: 0.3 | C9: Additional fractional FTE for 24/7 on-call beyond day coverage

Sheet Staffing_Model_KCCF
A1: Staffing Model — KCCF
A3: Role Group | B3: Activity | C3: Volume Driver | D3: Calc Type | E3: Annual Volume | F3: Min per Unit | G3: Positions | H3: Coverage Factor | I3: Required FTE
A4: Nursing Services | B4: Intake health review / BH screen | C4: bookings_annual | D4: per-encounter | E4: =Volumes_2025!B5 -> 11051 | F4: 30 | G4: — | H4: — | I4: =(E4*F4)/Productivity!$B$7 -> 3.320613
A5: Nursing Services | B5: Medication administration (med pass) | C5: med_passes_annual | D5: per-encounter | E5: =Volumes_2025!B17 -> 593190 | F5: 3 | G5: — | H5: — | I5: =(E5*F5)/Productivity!$B$7 -> 17.824219
A6: Nursing Services | B6: Infirmary RN coverage (24/7) | C6: — | D6: per-position | E6: — | F6: — | G6: 3 | H6: =Coverage_Factors!B4 -> 4.2 | I6: =G6*H6 -> 12.6
A7: Nursing Services | B7: Psych housing nursing rounds | C7: psych_housing_census_avg | D7: per-encounter | E7: =Volumes_2025!B12 -> 67 | F7: 7300 | G7: — | H7: — | I7: =(E7*F7)/Productivity!$B$7 -> 4.8988381
A8: Nursing Services | B8: Psych housing RN floor coverage (12hr) | C8: — | D8: per-position | E8: — | F8: — | G8: 2 | H8: =Coverage_Factors!B5 -> 2.1 | I8: =G8*H8 -> 4.2
A9: Nursing Services | B9: Suicide watch RN oversight (24/7) | C9: — | D9: per-position | E9: — | F9: — | G9: 1 | H9: =Coverage_Factors!B4 -> 4.2 | I9: =G9*H9 -> 4.2
A10: Nursing Services | B10: Withdrawal management nursing | C10: withdrawal_mgmt_census_avg | D10: per-encounter | E10: =Volumes_2025!B22 -> 47 | F10: 9125 | G10: — | H10: — | I10: =(E10*F10)/Productivity!$B$7 -> 4.295623
A11: Nursing Services | B11: Sick call triage & response | C11: sick_call_annual | D11: per-encounter | E11: =Volumes_2025!B15 -> 15640 | F11: 10 | G11: — | H11: — | I11: =(E11*F11)/Productivity!$B$7 -> 1.5665064
A12: Nursing Services | B12: Clinic floor nursing support | C12: clinic_visits_annual | D12: per-encounter | E12: =Volumes_2025!B16 -> 8625 | F12: 12 | G12: — | H12: — | I12: =(E12*F12)/Productivity!$B$7 -> 1.0366587
A13: Nursing Services | B13: KITE MH triage | C13: kite_mh_requests_annual | D13: per-encounter | E13: =Volumes_2025!B30 -> 6251 | F13: 5 | G13: — | H13: — | I13: =(E13*F13)/Productivity!$B$7 -> 0.31305088
A14: Nursing Services | B14: Chronic disease mgmt nursing | C14: adp_avg_combined | D14: per-encounter | E14: =Volumes_2025!B4 -> 790 | F14: 180 | G14: — | H14: — | I14: =(E14*F14)/Productivity!$B$7 -> 1.4242788
A15: Nursing Services | B15: Charge nurse positions | C15: — | D15: per-position | E15: — | F15: — | G15: 2 | H15: =Coverage_Factors!B4 -> 4.2 | I15: =G15*H15 -> 8.4
A16: Nursing Services | B16: HIV/STD testing nursing | C16: hiv_std_tests_annual | D16: per-encounter | E16: =Volumes_2025!B34 -> 4771 | F16: 20 | G16: — | H16: — | I16: =(E16*F16)/Productivity!$B$7 -> 0.95572917
A17: Nursing Services | B17: Nurse supervisors | C17: — | D17: per-position | E17: — | F17: — | G17: 3 | H17: =Coverage_Factors!B7 -> 1.2 | I17: =G17*H17 -> 3.6
A18: Social Services | B18: Release planning encounter work | C18: releases_annual | D18: per-encounter | E18: =Volumes_2025!B6 -> 10749 | F18: 25 | G18: — | H18: — | I18: =(E18*F18)/Productivity!$B$7 -> 2.6915565
A19: Social Services | B19: Coord. discharge social workers | C19: — | D19: per-position | E19: — | F19: — | G19: 3 | H19: =Coverage_Factors!B7 -> 1.2 | I19: =G19*H19 -> 3.6
A20: Social Services | B20: SUD assessment & counseling | C20: sud_assessments_annual | D20: per-encounter | E20: =Volumes_2025!B23 -> 2770 | F20: 60 | G20: — | H20: — | I20: =(E20*F20)/Productivity!$B$7 -> 1.6646635
A21: Social Services | B21: SUD professionals (program) | C21: — | D21: per-position | E21: — | F21: — | G21: 2 | H21: =Coverage_Factors!B7 -> 1.2 | I21: =G21*H21 -> 2.4
A22: Social Services | B22: MOUD group sessions encounter | C22: moud_census_avg | D22: per-encounter | E22: =Volumes_2025!B19 -> 82 | F22: 390 | G22: — | H22: — | I22: =(E22*F22)/Productivity!$B$7 -> 0.3203125
A23: Social Services | B23: Senior social workers / senior SUD | C23: — | D23: per-position | E23: — | F23: — | G23: 2 | H23: =Coverage_Factors!B7 -> 1.2 | I23: =G23*H23 -> 2.4
A24: Social Services | B24: Community diversion coordinators | C24: — | D24: per-position | E24: — | F24: — | G24: 2 | H24: =Coverage_Factors!B7 -> 1.2 | I24: =G24*H24 -> 2.4
A25: Social Services | B25: Community diversion support specialists | C25: — | D25: per-position | E25: — | F25: — | G25: 3 | H25: =Coverage_Factors!B7 -> 1.2 | I25: =G25*H25 -> 3.6
A26: Social Services | B26: Court clinicians (therapeutic courts) | C26: — | D26: per-position | E26: — | F26: — | G26: 3 | H26: =Coverage_Factors!B6 -> 1 | I26: =G26*H26 -> 3
A27: Social Services | B27: Court services support specialists | C27: — | D27: per-position | E27: — | F27: — | G27: 2 | H27: =Coverage_Factors!B6 -> 1 | I27: =G27*H27 -> 2
A28: Social Services | B28: Community health workers (peer support) | C28: — | D28: per-position | E28: — | F28: — | G28: 3 | H28: =Coverage_Factors!B7 -> 1.2 | I28: =G28*H28 -> 3.6
A29: Social Services | B29: Warm handoffs | C29: warm_handoffs_annual | D29: per-encounter | E29: =Volumes_2025!B28 -> 167 | F29: 45 | G29: — | H29: — | I29: =(E29*F29)/Productivity!$B$7 -> 0.075270433
A30: Social Services | B30: Community referrals | C30: community_referrals_annual | D30: per-encounter | E30: =Volumes_2025!B29 -> 2216 | F30: 15 | G30: — | H30: — | I30: =(E30*F30)/Productivity!$B$7 -> 0.33293269
A31: Social Services | B31: Pre-release services (1115 Waiver) | C31: pre_release_services_annual | D31: per-encounter | E31: =Volumes_2025!B38 -> 0 | F31: 120 | G31: — | H31: — | I31: =(E31*F31)/Productivity!$B$7 -> 0
A32: Social Services | B32: Program managers (Social Services, Coord Discharge, Diversion) | C32: — | D32: per-position | E32: — | F32: — | G32: 2 | H32: =Coverage_Factors!B7 -> 1.2 | I32: =G32*H32 -> 2.4
A33: Social Services | B33: Social Services Mgr + Clinical Supervisors | C33: — | D33: per-position | E33: — | F33: — | G33: 2 | H33: =Coverage_Factors!B7 -> 1.2 | I33: =G33*H33 -> 2.4
A34: Social Services | B34: Reentry Demo project manager + assistant | C34: — | D34: per-position | E34: — | F34: — | G34: 1 | H34: =Coverage_Factors!B6 -> 1 | I34: =G34*H34 -> 1
A35: Psychiatric Services | B35: Psych clinic encounters (provider) | C35: psych_clinic_appts_completed | D35: per-encounter | E35: =Volumes_2025!B10 -> 1947 | F35: 40 | G35: — | H35: — | I35: =(E35*F35)/Productivity!$B$7 -> 0.78004808
A36: Psychiatric Services | B36: Psych housing encounters (provider) | C36: psych_housing_appts_completed | D36: per-encounter | E36: =Volumes_2025!B11 -> 3493 | F36: 20 | G36: — | H36: — | I36: =(E36*F36)/Productivity!$B$7 -> 0.69971955
A37: Psychiatric Services | B37: Crisis counseling events | C37: crisis_counseling_annual | D37: per-encounter | E37: =Volumes_2025!B31 -> 1680 | F37: 35 | G37: — | H37: — | I37: =(E37*F37)/Productivity!$B$7 -> 0.58894231
A38: Psychiatric Services | B38: ITA evaluations | C38: ita_evaluations_annual | D38: per-encounter | E38: =Volumes_2025!B32 -> 780 | F38: 45 | G38: — | H38: — | I38: =(E38*F38)/Productivity!$B$7 -> 0.3515625
A39: Psychiatric Services | B39: Documentation + chart review overhead | C39: psych_clinic_appts_completed | D39: per-encounter | E39: =Volumes_2025!B10 -> 1947 | F39: 12 | G39: — | H39: — | I39: =(E39*F39)/Productivity!$B$7 -> 0.23401442
A40: Psychiatric Services | B40: Psychiatric Evaluation Specialists (PES) | C40: — | D40: per-position | E40: — | F40: — | G40: 5 | H40: =Coverage_Factors!B7 -> 1.2 | I40: =G40*H40 -> 6
A41: Psychiatric Services | B41: PES evening/weekend coverage | C41: — | D41: per-position | E41: — | F41: — | G41: 1 | H41: =Coverage_Factors!B8 -> 1.6 | I41: =G41*H41 -> 1.6
...

Sheet Staffing_Model_MRJC
A1: Staffing Model — MRJC
A3: Role Group | B3: Activity | C3: Volume Driver | D3: Calc Type | E3: Annual Volume | F3: Min per Unit | G3: Positions | H3: Coverage Factor | I3: Required FTE
A4: Nursing Services | B4: Intake health review / BH screen | C4: bookings_annual | D4: per-encounter | E4: =Volumes_2025!C5 -> 6905 | F4: 30 | G4: — | H4: — | I4: =(E4*F4)/Productivity!$B$7 -> 2.0748197
A5: Nursing Services | B5: Medication administration (med pass) | C5: med_passes_annual | D5: per-encounter | E5: =Volumes_2025!C17 -> 463526 | F5: 3 | G5: — | H5: — | I5: =(E5*F5)/Productivity!$B$7 -> 13.928065
A6: Nursing Services | B6: Infirmary RN coverage (24/7) | C6: — | D6: per-position | E6: — | F6: — | G6: 3 | H6: =Coverage_Factors!B4 -> 4.2 | I6: =G6*H6 -> 12.6
A7: Nursing Services | B7: Psych housing nursing rounds | C7: psych_housing_census_avg | D7: per-encounter | E7: =Volumes_2025!C12 -> 52 | F7: 7300 | G7: — | H7: — | I7: =(E7*F7)/Productivity!$B$7 -> 3.8020833
A8: Nursing Services | B8: Psych housing RN floor coverage (12hr) | C8: — | D8: per-position | E8: — | F8: — | G8: 0 | H8: =Coverage_Factors!B5 -> 2.1 | I8: =G8*H8 -> 0
A9: Nursing Services | B9: Suicide watch RN oversight (24/7) | C9: — | D9: per-position | E9: — | F9: — | G9: 0 | H9: =Coverage_Factors!B4 -> 4.2 | I9: =G9*H9 -> 0
A10: Nursing Services | B10: Withdrawal management nursing | C10: withdrawal_mgmt_census_avg | D10: per-encounter | E10: =Volumes_2025!C22 -> 36 | F10: 9125 | G10: — | H10: — | I10: =(E10*F10)/Productivity!$B$7 -> 3.2902644
A11: Nursing Services | B11: Sick call triage & response | C11: sick_call_annual | D11: per-encounter | E11: =Volumes_2025!C15 -> 12224 | F11: 10 | G11: — | H11: — | I11: =(E11*F11)/Productivity!$B$7 -> 1.224359
A12: Nursing Services | B12: Clinic floor nursing support | C12: clinic_visits_annual | D12: per-encounter | E12: =Volumes_2025!C16 -> 6405 | F12: 12 | G12: — | H12: — | I12: =(E12*F12)/Productivity!$B$7 -> 0.76983173
A13: Nursing Services | B13: KITE MH triage | C13: kite_mh_requests_annual | D13: per-encounter | E13: =Volumes_2025!C30 -> 4940 | F13: 5 | G13: — | H13: — | I13: =(E13*F13)/Productivity!$B$7 -> 0.24739583
A14: Nursing Services | B14: Chronic disease mgmt nursing | C14: adp_avg_combined | D14: per-encounter | E14: =Volumes_2025!C4 -> 621 | F14: 180 | G14: — | H14: — | I14: =(E14*F14)/Productivity!$B$7 -> 1.1195913
A15: Nursing Services | B15: Charge nurse positions | C15: — | D15: per-position | E15: — | F15: — | G15: 2 | H15: =Coverage_Factors!B4 -> 4.2 | I15: =G15*H15 -> 8.4
A16: Nursing Services | B16: HIV/STD testing nursing | C16: hiv_std_tests_annual | D16: per-encounter | E16: =Volumes_2025!C34 -> 2939 | F16: 20 | G16: — | H16: — | I16: =(E16*F16)/Productivity!$B$7 -> 0.58874199
A17: Nursing Services | B17: Nurse supervisors | C17: — | D17: per-position | E17: — | F17: — | G17: 2 | H17: =Coverage_Factors!B7 -> 1.2 | I17: =G17*H17 -> 2.4
A18: Social Services | B18: Release planning encounter work | C18: releases_annual | D18: per-encounter | E18: =Volumes_2025!C6 -> 6694 | F18: 25 | G18: — | H18: — | I18: =(E18*F18)/Productivity!$B$7 -> 1.6761819
A19: Social Services | B19: Coord. discharge social workers | C19: — | D19: per-position | E19: — | F19: — | G19: 2 | H19: =Coverage_Factors!B7 -> 1.2 | I19: =G19*H19 -> 2.4
A20: Social Services | B20: SUD assessment & counseling | C20: sud_assessments_annual | D20: per-encounter | E20: =Volumes_2025!C23 -> 2771 | F20: 60 | G20: — | H20: — | I20: =(E20*F20)/Productivity!$B$7 -> 1.6652644
A21: Social Services | B21: SUD professionals (program) | C21: — | D21: per-position | E21: — | F21: — | G21: 2 | H21: =Coverage_Factors!B7 -> 1.2 | I21: =G21*H21 -> 2.4
A22: Social Services | B22: MOUD group sessions encounter | C22: moud_census_avg | D22: per-encounter | E22: =Volumes_2025!C19 -> 123 | F22: 390 | G22: — | H22: — | I22: =(E22*F22)/Productivity!$B$7 -> 0.48046875
A23: Social Services | B23: Senior social workers / senior SUD | C23: — | D23: per-position | E23: — | F23: — | G23: 1 | H23: =Coverage_Factors!B7 -> 1.2 | I23: =G23*H23 -> 1.2
A24: Social Services | B24: Community diversion coordinators | C24: — | D24: per-position | E24: — | F24: — | G24: 1 | H24: =Coverage_Factors!B7 -> 1.2 | I24: =G24*H24 -> 1.2
A25: Social Services | B25: Community diversion support specialists | C25: — | D25: per-position | E25: — | F25: — | G25: 1 | H25: =Coverage_Factors!B7 -> 1.2 | I25: =G25*H25 -> 1.2
A26: Social Services | B26: Court clinicians (therapeutic courts) | C26: — | D26: per-position | E26: — | F26: — | G26: 1 | H26: =Coverage_Factors!B6 -> 1 | I26: =G26*H26 -> 1
A27: Social Services | B27: Court services support specialists | C27: — | D27: per-position | E27: — | F27: — | G27: 1 | H27: =Coverage_Factors!B6 -> 1 | I27: =G27*H27 -> 1
A28: Social Services | B28: Community health workers (peer support) | C28: — | D28: per-position | E28: — | F28: — | G28: 2 | H28: =Coverage_Factors!B7 -> 1.2 | I28: =G28*H28 -> 2.4
A29: Social Services | B29: Warm handoffs | C29: warm_handoffs_annual | D29: per-encounter | E29: =Volumes_2025!C28 -> 66 | F29: 45 | G29: — | H29: — | I29: =(E29*F29)/Productivity!$B$7 -> 0.029747596
A30: Social Services | B30: Community referrals | C30: community_referrals_annual | D30: per-encounter | E30: =Volumes_2025!C29 -> 1313 | F30: 15 | G30: — | H30: — | I30: =(E30*F30)/Productivity!$B$7 -> 0.19726562
A31: Social Services | B31: Pre-release services (1115 Waiver) | C31: pre_release_services_annual | D31: per-encounter | E31: =Volumes_2025!C38 -> 0 | F31: 120 | G31: — | H31: — | I31: =(E31*F31)/Productivity!$B$7 -> 0
A32: Social Services | B32: Program managers (Social Services, Coord Discharge, Diversion) | C32: — | D32: per-position | E32: — | F32: — | G32: 1 | H32: =Coverage_Factors!B7 -> 1.2 | I32: =G32*H32 -> 1.2
A33: Social Services | B33: Social Services Mgr + Clinical Supervisors | C33: — | D33: per-position | E33: — | F33: — | G33: 1 | H33: =Coverage_Factors!B7 -> 1.2 | I33: =G33*H33 -> 1.2
A34: Social Services | B34: Reentry Demo project manager + assistant | C34: — | D34: per-position | E34: — | F34: — | G34: 1 | H34: =Coverage_Factors!B6 -> 1 | I34: =G34*H34 -> 1
A35: Psychiatric Services | B35: Psych clinic encounters (provider) | C35: psych_clinic_appts_completed | D35: per-encounter | E35: =Volumes_2025!C10 -> 2020 | F35: 40 | G35: — | H35: — | I35: =(E35*F35)/Productivity!$B$7 -> 0.80929487
A36: Psychiatric Services | B36: Psych housing encounters (provider) | C36: psych_housing_appts_completed | D36: per-encounter | E36: =Volumes_2025!C11 -> 3451 | F36: 20 | G36: — | H36: — | I36: =(E36*F36)/Productivity!$B$7 -> 0.69130609
A37: Psychiatric Services | B37: Crisis counseling events | C37: crisis_counseling_annual | D37: per-encounter | E37: =Volumes_2025!C31 -> 1322 | F37: 35 | G37: — | H37: — | I37: =(E37*F37)/Productivity!$B$7 -> 0.46344151
A38: Psychiatric Services | B38: ITA evaluations | C38: ita_evaluations_annual | D38: per-encounter | E38: =Volumes_2025!C32 -> 736 | F38: 45 | G38: — | H38: — | I38: =(E38*F38)/Productivity!$B$7 -> 0.33173077
A39: Psychiatric Services | B39: Documentation + chart review overhead | C39: psych_clinic_appts_completed | D39: per-encounter | E39: =Volumes_2025!C10 -> 2020 | F39: 12 | G39: — | H39: — | I39: =(E39*F39)/Productivity!$B$7 -> 0.24278846
A40: Psychiatric Services | B40: Psychiatric Evaluation Specialists (PES) | C40: — | D40: per-position | E40: — | F40: — | G40: 3 | H40: =Coverage_Factors!B7 -> 1.2 | I40: =G40*H40 -> 3.6
A41: Psychiatric Services | B41: PES evening/weekend coverage | C41: — | D41: per-position | E41: — | F41: — | G41: 1 | H41: =Coverage_Factors!B8 -> 1.6 | I41: =G41*H41 -> 1.6
...

Sheet Summary
A1: Staffing Model Summary — FTE by Role × Facility
A3: Role Group | B3: KCCF Required | C3: MRJC Required | D3: Total Required | E3: Target Share | F3: Current Filled (est.) | G3: Gap vs Current | H3: % Over/Under
A4: Nursing Services | B4: =SUMIF(Staffing_Model_KCCF!A:A,A4,Staffing_Model_KCCF!I:I) -> 68.635517 | C4: =SUMIF(Staffing_Model_MRJC!A:A,A4,Staffing_Model_MRJC!I:I) -> 50.445152 | D4: =B4+C4 -> 119.08067 | E4: 0.425 | F4: =E4*$B$14 -> 106.25 | G4: =D4-F4 -> 12.830669 | H4: =IFERROR((D4-F4)/F4,0) -> 0.12075924
A5: Social Services | B5: =SUMIF(Staffing_Model_KCCF!A:A,A5,Staffing_Model_KCCF!I:I) -> 33.884736 | C5: =SUMIF(Staffing_Model_MRJC!A:A,A5,Staffing_Model_MRJC!I:I) -> 20.248928 | D5: =B5+C5 -> 54.133664 | E5: 0.179 | F5: =E5*$B$14 -> 44.75 | G5: =D5-F5 -> 9.3836639 | H5: =IFERROR((D5-F5)/F5,0) -> 0.20969081
A6: Psychiatric Services | B6: =SUMIF(Staffing_Model_KCCF!A:A,A6,Staffing_Model_KCCF!I:I) -> 12.754287 | C6: =SUMIF(Staffing_Model_MRJC!A:A,A6,Staffing_Model_MRJC!I:I) -> 7.7385617 | D6: =B6+C6 -> 20.492849 | E6: 0.091 | F6: =E6*$B$14 -> 22.75 | G6: =D6-F6 -> -2.2571514 | H6: =IFERROR((D6-F6)/F6,0) -> -0.099215448
A7: Health Info & Clinical Apps | B7: =SUMIF(Staffing_Model_KCCF!A:A,A7,Staffing_Model_KCCF!I:I) -> 11.913722 | C7: =SUMIF(Staffing_Model_MRJC!A:A,A7,Staffing_Model_MRJC!I:I) -> 5.0845954 | D7: =B7+C7 -> 16.998317 | E7: 0.081 | F7: =E7*$B$14 -> 20.25 | G7: =D7-F7 -> -3.2516827 | H7: =IFERROR((D7-F7)/F7,0) -> -0.16057692
A8: Medical & Dental Providers | B8: =SUMIF(Staffing_Model_KCCF!A:A,A8,Staffing_Model_KCCF!I:I) -> 7.9470152 | C8: =SUMIF(Staffing_Model_MRJC!A:A,A8,Staffing_Model_MRJC!I:I) -> 5.9175781 | D8: =B8+C8 -> 13.864593 | E8: 0.066 | F8: =E8*$B$14 -> 16.5 | G8: =D8-F8 -> -2.6354067 | H8: =IFERROR((D8-F8)/F8,0) -> -0.15972162
A9: Pharmacy Services | B9: =SUMIF(Staffing_Model_KCCF!A:A,A9,Staffing_Model_KCCF!I:I) -> 10.765325 | C9: =SUMIF(Staffing_Model_MRJC!A:A,A9,Staffing_Model_MRJC!I:I) -> 8.0964944 | D9: =B9+C9 -> 18.861819 | E9: 0.066 | F9: =E9*$B$14 -> 16.5 | G9: =D9-F9 -> 2.3618189 | H9: =IFERROR((D9-F9)/F9,0) -> 0.14314054
A10: Clinical Operations | B10: =SUMIF(Staffing_Model_KCCF!A:A,A10,Staffing_Model_KCCF!I:I) -> 10.4 | C10: =SUMIF(Staffing_Model_MRJC!A:A,A10,Staffing_Model_MRJC!I:I) -> 4.6 | D10: =B10+C10 -> 15 | E10: 0.055 | F10: =E10*$B$14 -> 13.75 | G10: =D10-F10 -> 1.25 | H10: =IFERROR((D10-F10)/F10,0) -> 0.090909091
A11: Administration | B11: =SUMIF(Staffing_Model_KCCF!A:A,A11,Staffing_Model_KCCF!I:I) -> 10.4 | C11: =SUMIF(Staffing_Model_MRJC!A:A,A11,Staffing_Model_MRJC!I:I) -> 0 | D11: =B11+C11 -> 10.4 | E11: 0.037 | F11: =E11*$B$14 -> 9.25 | G11: =D11-F11 -> 1.15 | H11: =IFERROR((D11-F11)/F11,0) -> 0.12432432
A12: TOTAL | B12: =SUM(B4:B11) -> 166.7006 | C12: =SUM(C4:C11) -> 102.13131 | D12: =SUM(D4:D11) -> 268.83191 | E12: =SUM(E4:E11) -> 1 | F12: =SUM(F4:F11) -> 250 | G12: =D12-F12 -> 18.831911 | H12: =IFERROR((D12-F12)/F12,0) -> 0.075327644
A14: Division baseline FTE: | B14: 250
A15: (From Feb 4, 2026 JHS Council presentation — '250+ employees, $60M+ budget')
A17: Total by Facility
A18: KCCF Total Required FTE | B18: =SUM(B4:B11) -> 166.7006
A19: MRJC Total Required FTE | B19: =SUM(C4:C11) -> 102.13131
A20: Combined Total Required FTE | B20: =B18+B19 -> 268.83191

Sheet Scenarios
A1: Scenario Modeling — Incremental FTE for 2026 Initiatives by Facility
A3: Scenario | B3: KCCF Δ | C3: MRJC Δ | D3: Total Δ | E3: New Total | F3: Notes
A4: Baseline (current 2025) | B4: 0 | C4: 0 | D4: =B4+C4 -> 0 | E4: =Summary!B20+D4 -> 268.83191 | F4: Full-year 2025 workload at current service standards.
A5: Rec #1: tightened wait-time standard (25-day median) | B5: 3 | C5: 3 | D5: =B5+C5 -> 6 | E5: =Summary!B20+D5 -> 274.83191 | F5: +6 Psychiatric Services total; ~even split. 1-2 providers + 1-2 PES per facility.
A6: Rec #7/9: 14-day release supply for all eligible | B6: 5 | C6: 3 | D6: =B6+C6 -> 8 | E6: =Summary!B20+D6 -> 276.83191 | F6: +8 across pharmacy, social services, nursing. KCCF-heavier due to bigger release volume.
A7: Rec #8: 24/7 release pharmacy & planning | B7: 7 | C7: 4 | D7: =B7+C7 -> 11 | E7: =Summary!B20+D7 -> 279.83191 | F7: +11 across both sites; KCCF absorbs more because of higher after-hours release volume.
A8: 1115 Waiver go-live (July 2026) first 6 months | B8: 9 | C8: 6 | D8: =B8+C8 -> 15 | E8: =Summary!B20+D8 -> 283.83191 | F8: +15 Social Services + HI&CA + Admin. Load follows release volume.
A9: 1115 Waiver + 30-day supply for ALL releases | B9: 15 | C9: 9 | D9: =B9+C9 -> 24 | E9: =Summary!B20+D9 -> 292.83191 | F9: +24 cumulative. Pharmacy dominates the incremental load.
A10: MOUD census doubles to ~480 (projected 2027) | B10: 3 | C10: 4 | D10: =B10+C10 -> 7 | E10: =Summary!B20+D10 -> 275.83191 | F10: +7 nursing / pharmacy / medical. MRJC-heavier: larger MOUD census.
A11: NCCHC BH-standard adoption (Rec #12) ongoing | B11: 2 | C11: 0 | D11: =B11+C11 -> 2 | E11: =Summary!B20+D11 -> 270.83191 | F11: +2 accreditation & QI; Division-wide, based at KCCF.
A12: All 2026 initiatives combined (Dec 2026 end-state) | B12: 19 | C12: 13 | D12: =B12+C12 -> 32 | E12: =Summary!B20+D12 -> 300.83191 | F12: Rec #1 + Rec #7/8/9 (14-day) + 1115 Waiver + MOUD growth + NCCHC.
A15: Note: Facility-level ΔFTE values are design estimates based on the activity math in the Staffing_Model sheets. For a formal budget request, re-run the per-facility sheets with updated volumes / standards for each scenario.
